Workbook
Name Slicer_Make: #N/A

Sheet Raw Data
A1: Car | B1: Condition | C1: Mileage | D1: Price | E1: Basics Info | F1: Vehicle History Info | G1: Vehicle Reviews Info | H1: Seller Rating | I1: Seller Rating Count | J1: Seller Address
A2: 2024 Lexus LC 500 Base | B2: New | C2: 0 mi. | D2: $112,865MSRP $118,865 | E2: {'Exterior color': ' Caviar ', 'Interior color': 'Black ', 'Drivetrain': 'Rear-wheel Drive ', 'MPG': ' 15â€“25Based on EPA mileage ratings. Use for comparison purposes only. Actual mileage will vary depending on driving conditions, driving habits, vehicle maintenance, and other factors.', 'Fuel type': 'Gasoline ', 'Transmission': '10-Speed Automatic', 'Engine': '5.0L V8 32V PDI DOHC', 'VIN': ' JTHNPAAY2RA108024 ', 'Stock #': ' R087 ', 'Mileage': ' 0 mi. '} | F2: {} | G2: {} | H2: 4.7 | I2: (1,261 reviews) | J2: 1250 W Division St Chicago, IL 60642
A3: 2007 Acura TSX Base | B3: Used | C3: 61,110 mi. | D3: 11295 | E3: {'Exterior color': ' Alabaster Silver Metallic ', 'Interior color': 'â€“ ', 'Drivetrain': 'Front-wheel Drive ', 'MPG': ' 22â€“31Based on EPA mileage ratings. Use for comparison purposes only. Actual mileage will vary depending on driving conditions, driving habits, vehicle maintenance, and other factors.', 'Fuel type': 'Gasoline ', 'Transmission': 'Automatic', 'Engine': '2.4L I-4 DOHC, i-VTEC variable valve control, premium unleaded,', 'VIN': ' JH4CL96827C013765 ', 'Stock #': ' A40896A ', 'Mileage': ' 61,110 mi. '} | F3: {'Accidents or damage': 'At least 1 accident or damage reported', '1-owner vehicle': 'Yes', 'Personal use only': 'Yes'} | G3: {} | H3: 4.2 | I3: (440 reviews) | J3: 1301 N Elston Ave Chicago, IL 60642
A4: 2016 McLaren 675LT Base | B4: Used | C4: 6,305 mi. | D4: $219,997$5,464 price drop | E4: {'Exterior color': ' McLaren Orange ', 'Interior color': 'Carbon Black ', 'Drivetrain': 'Rear-wheel Drive ', 'MPG': ' â€“', 'Fuel type': 'Gasoline ', 'Transmission': '7-Speed Automatic with Auto-Shift', 'Engine': '3.8L V8 32V MPFI DOHC Twin Turbo', 'VIN': ' SBM11RAA7GW675095 ', 'Stock #': ' K2338 ', 'Mileage': ' 6,305 mi. '} | F4: {'Accidents or damage': 'At least 1 accident or damage reported', '1-owner vehicle': 'No', 'Personal use only': 'No'} | G4: {'Comfort': '5.0', 'Interior': '5.0', 'Performance': '5.0', 'Value': '5.0', 'Exterior': '5.0', 'Reliability': '5.0'} | H4: 3.1 | I4: (421 reviews) | J4: 1561 N Fremont St Chicago, IL 60642
A5: 2016 Audi TTS 2.0T quattro | B5: Used | C5: 65,715 mi. | D5: 23999 | E5: {'Exterior color': ' Black ', 'Interior color': 'Black ', 'Drivetrain': 'All-wheel Drive ', 'MPG': ' 23â€“27Based on EPA mileage ratings. Use for comparison purposes only. Actual mileage will vary depending on driving conditions, driving habits, vehicle maintenance, and other factors.', 'Fuel type': 'Gasoline ', 'Transmission': '6-Speed Automatic with Auto-Shift', 'Engine': '2.0L I4 16V GDI DOHC Turbo', 'VIN': ' TRUC1AFV1G1019119 ', 'Stock #': ' 3949 ', 'Mileage': ' 65,715 mi. '} | F5: {'Accidents or damage': 'At least 1 accident or damage reported', 'Clean title': 'Yes', '1-owner vehicle': 'No', 'Personal use only': 'Yes'} | G5: {'Comfort': '3.0', 'Interior': '5.0', 'Performance': '5.0', 'Value': '5.0', 'Exterior': '5.0', 'Reliability': '5.0'} | H5: 3.6 | I5: (123 reviews) | J5: 560 E North Ave West Chicago, IL 60185
A6: 2018 BMW 740e xDrive iPerformance | B6: Used | C6: 19,830 mi. | D6: $39,799$100 price drop | E6: {'Exterior color': ' Imperial Blue Metallic ', 'Interior color': 'Black ', 'Drivetrain': 'All-wheel Drive ', 'MPG': ' 0â€“0Based on EPA mileage ratings. Use for comparison purposes only. Actual mileage will vary depending on driving conditions, driving habits, vehicle maintenance, and other factors.', 'Fuel type': 'Gasoline ', 'Transmission': '8-Speed Automatic', 'Engine': '2L I-4 gasoline direct injection, DOHC, Double VANOS variable va', 'VIN': ' WBA7J2C57JG938534 ', 'Stock #': ' A6006 ', 'Mileage': ' 19,830 mi. '} | F6: {'Accidents or damage': 'None reported', 'Clean title': 'Yes', '1-owner vehicle': 'Yes', 'Personal use only': 'No'} | G6: {'Comfort': '5.0', 'Interior': '5.0', 'Performance': '5.0', 'Value': '5.0', 'Exterior': '5.0', 'Reliability': '5.0'} | H6: 4.4 | I6: (91 reviews) | J6: 6539 Ogden Ave Berwyn, IL 60402
A7: 2019 Jeep Cherokee Limited | B7: Used | C7: 52,245 mi. | D7: $22,966$173 price drop | E7: {'Exterior color': ' Diamond Black ', 'Interior color': 'Black ', 'Drivetrain': 'Four-wheel Drive ', 'MPG': ' 19â€“27Based on EPA mileage ratings. Use for comparison purposes only. Actual mileage will vary depending on driving conditions, driving habits, vehicle maintenance, and other factors.', 'Fuel type': 'Gasoline ', 'Transmission': '9-Speed Automatic', 'Engine': '3.2L V6 24V MPFI DOHC', 'VIN': ' 1C4PJMDX4KD139201 ', 'Stock #': ' Y17217A ', 'Mileage': ' 52,245 mi. '} | F7: {'Accidents or damage': 'At least 1 accident or damage reported', '1-owner vehicle': 'No', 'Personal use only': 'No'} | G7: {} | H7: 4.2 | I7: (3,030 reviews) | J7: 6750 W Grand Ave Chicago, IL 60707
A8: 2019 Cadillac CT6 3.6L Luxury | B8: Used | C8: 94,008 mi. | D8: $26,995$183 price drop | E8: {'Exterior color': ' Black ', 'Interior color': 'Black ', 'Drivetrain': 'All-wheel Drive ', 'MPG': ' 18â€“27Based on EPA mileage ratings. Use for comparison purposes only. Actual mileage will vary depending on driving conditions, driving habits, vehicle maintenance, and other factors.', 'Fuel type': 'Gasoline ', 'Transmission': 'Automatic', 'Engine': '3.6L V-6 gasoline direct injection, DOHC, VVT variable valve con', 'VIN': ' 1G6KB5RS1KU131814 ', 'Stock #': ' 8378 ', 'Mileage': ' 94,008 mi. '} | F8: {'Accidents or damage': 'At least 1 accident or damage reported', '1-owner vehicle': 'No', 'Personal use only': 'No'} | G8: {} | H8: 4.1 | I8: (50 reviews) | J8: 7158 Harlem Ave Bridgeview, IL 60455
A9: 2012 Nissan NV Cargo S | B9: Used | C9: 110,202 mi. | D9: 14985 | E9: {'Exterior color': ' Blizzard ', 'Interior color': 'Gray ', 'Drivetrain': 'Rear-wheel Drive ', 'MPG': ' â€“', 'Fuel type': 'Gasoline ', 'Transmission': 'Automatic', 'Engine': '5.6L V8 32V MPFI DOHC', 'VIN': ' 1N6AF0KX9CN103838 ', 'Stock #': ' 8418 ', 'Mileage': ' 110,202 mi. '} | F9: {'Accidents or damage': 'At least 1 accident or damage reported', 'Clean title': 'Yes', '1-owner vehicle': 'No', 'Personal use only': 'No'} | G9: {'Comfort': '5.0', 'Interior': '5.0', 'Performance': '5.0', 'Value': '4.0', 'Exterior': '4.0', 'Reliability': '3.0'} | H9: 3.6 | I9: (64 reviews) | J9: 6007 S Archer Rd Summit, IL 60501
A10: 2008 Chrysler Sebring Touring | B10: Used | C10: 77,893 mi. | D10: 7995 | E10: {'Exterior color': ' Silver ', 'Interior color': 'Gray ', 'Drivetrain': 'Front-wheel Drive ', 'MPG': ' 26â€“26Based on EPA mileage ratings. Use for comparison purposes only. Actual mileage will vary depending on driving conditions, driving habits, vehicle maintenance, and other factors.', 'Fuel type': 'E85 Flex Fuel ', 'Transmission': 'Automatic 4-Speed', 'Engine': '2.7L V6', 'VIN': ' 1C3LC55R58N689769 ', 'Stock #': ' 8N689769STK ', 'Mileage': ' 77,893 mi. '} | F10: {'Accidents or damage': 'None reported', '1-owner vehicle': 'No', 'Personal use only': 'Yes'} | G10: {} | H10: 3.5 | I10: (43 reviews) | J10: 1210 25th Ave Melrose Park, IL 60160
A11: 2012 Ford E250 Cargo | B11: Used | C11: 106,430 mi. | D11: $15,750$540 price drop | E11: {'Exterior color': ' White ', 'Interior color': 'Gray ', 'Drivetrain': 'Rear-wheel Drive ', 'MPG': ' 17â€“17Based on EPA mileage ratings. Use for comparison purposes only. Actual mileage will vary depending on driving conditions, driving habits, vehicle maintenance, and other factors.', 'Fuel type': 'E85 Flex Fuel ', 'Transmission': 'Automatic 4-Speed', 'Engine': '4.6L V8', 'VIN': ' 1FTNE2EW9CDA52319 ', 'Stock #': ' T0137 ', 'Mileage': ' 106,430 mi. '} | F11: {'Accidents or damage': 'None reported', 'Clean title': 'No', '1-owner vehicle': 'No', 'Personal use only': 'No'} | G11: {'Comfort': '4.0', 'Interior': '4.0', 'Performance': '4.0', 'Value': '5.0', 'Exterior': '4.0', 'Reliability': '5.0'} | J11: 6400 Harlem Ave Summit, IL 60501
A12: 2013 Toyota Prius v Five | B12: Used | C12: 155,600 mi. | D12: 12995 | E12: {'Exterior color': ' Blue ', 'Interior color': 'Gray ', 'Drivetrain': 'Front-wheel Drive ', 'MPG': ' 44â€“40Based on EPA mileage ratings. Use for comparison purposes only. Actual mileage will vary depending on driving conditions, driving habits, vehicle maintenance, and other factors.', 'Fuel type': 'Gasoline ', 'Transmission': 'Automatic', 'Engine': '1.8L I-4 DOHC, VVT-i variable valve control, regular unleaded, e', 'VIN': ' JTDZN3EU9D3206492 ', 'Stock #': ' GA-206492 ', 'Mileage': ' 155,600 mi. '} | F12: {'Accidents or damage': 'At least 1 accident or damage reported', '1-owner vehicle': 'No', 'Personal use only': 'Yes'} | G12: {'Comfort': '5.0', 'Interior': '4.0', 'Performance': '4.0', 'Value': '5.0', 'Exterior': '4.0', 'Reliability': '5.0'} | J12: 5050 Dempster Street Skokie, IL 60077
A13: 2002 BMW 745 Li | B13: Used | C13: 146,000 mi. | D13: 4599 | E13: {'Exterior color': ' White ', 'Interior color': 'Beige ', 'Drivetrain': 'Rear-wheel Drive ', 'Fuel type': 'Gasoline ', 'Transmission': 'A/T', 'Engine': '325.0HP 4.4L 8 Cylinder Engine Gasoline Fuel', 'VIN': ' WBAGN634X2DR03993 ', 'Mileage': ' 146,000 mi. '} | F13: {'Accidents or damage': 'None reported', 'Clean title': 'Yes', '1-owner vehicle': 'No', 'Personal use only': 'Yes'} | G13: {}
A14: 2020 INFINITI Q60 3.0t Red Sport 400 | B14: Used | C14: 22,901 mi. | D14: 38713 | E14: {'Exterior color': ' Iridium Blue ', 'Interior color': 'Blue ', 'Drivetrain': 'Rear-wheel Drive ', 'MPG': ' 20â€“27Based on EPA mileage ratings. Use for comparison purposes only. Actual mileage will vary depending on driving conditions, driving habits, vehicle maintenance, and other factors.', 'Fuel type': 'Gasoline ', 'Transmission': '7-Speed Automatic', 'Engine': '3.0L V6 24V GDI DOHC Twin Turbo', 'VIN': ' JN1FV7EK1LM400180 ', 'Stock #': ' M91221 ', 'Mileage': ' 22,901 mi. '} | F14: {'Accidents or damage': 'None reported', '1-owner vehicle': 'Yes', 'Personal use only': 'Yes'} | G14: {} | H14: 4.1 | I14: (591 reviews) | J14: 6750 West 95th Street Oak Lawn, IL 60453
A15: 2014 Volkswagen Beetle 1.8T | B15: Used | C15: 48,650 mi. | D15: 16988 | E15: {'Exterior color': ' Platinum Gray Metallic ', 'Interior color': 'Titan Black ', 'Drivetrain': 'Front-wheel Drive ', 'MPG': ' 25â€“33Based on EPA mileage ratings. Use for comparison purposes only. Actual mileage will vary depending on driving conditions, driving habits, vehicle maintenance, and other factors.', 'Fuel type': 'Gasoline ', 'Transmission': '6-Speed Automatic', 'Engine': '1.8L I4 16V GDI DOHC Turbo', 'VIN': ' 3VWJ17AT3EM659954 ', 'Stock #': ' P7459VW ', 'Mileage': ' 48,650 mi. '} | F15: {'Accidents or damage': 'None reported', '1-owner vehicle': 'Yes', 'Personal use only': 'Yes'} | G15: {} | H15: 4.5 | I15: (1,555 reviews) | J15: 241 Waukegan Rd Glenview, IL 60025
A16: 2015 BMW M235 i | B16: Used | C16: 73,660 mi. | D16: 22843 | E16: {'Exterior color': ' Glacier Silver Metallic ', 'Interior color': 'â€“ ', 'Drivetrain': 'Rear-wheel Drive ', 'MPG': ' 21â€“32Based on EPA mileage ratings. Use for comparison purposes only. Actual mileage will vary depending on driving conditions, driving habits, vehicle maintenance, and other factors.', 'Fuel type': 'Gasoline ', 'Transmission': '8-Speed Automatic', 'Engine': '3.0L I6 24V GDI DOHC Turbo', 'VIN': ' WBA1J7C59FV358577 ', 'Stock #': ' R6301 ', 'Mileage': ' 73,660 mi. '} | F16: {'Accidents or damage': 'None reported', 'Clean title': 'Yes', '1-owner vehicle': 'No', 'Personal use only': 'Yes'} | G16: {} | H16: 4 | I16: (288 reviews) | J16: 11201 S Harlem Ave Worth, IL 60482
A17: 2004 BMW 745 745i | B17: Used | C17: 119,263 mi. | D17: 7999 | E17: {'Exterior color': ' Gold ', 'Interior color': 'Tan ', 'Drivetrain': 'Rear-wheel Drive ', 'MPG': ' 18â€“26Based on EPA mileage ratings. Use for comparison purposes only. Actual mileage will vary depending on driving conditions, driving habits, vehicle maintenance, and other factors.', 'Fuel type': 'Gasoline ', 'Transmission': '6-speed Steptronic automatic transmission w/OD-inc', 'Engine': '4.4L (268) DOHC EFI 32-valve aluminum V8 engine w/variable valve', 'VIN': ' WBAGL63424DP69960 ', 'Stock #': ' EM-P69960 ', 'Mileage': ' 119,263 mi. '} | F17: {'Accidents or damage': 'None reported', '1-owner vehicle': 'No', 'Personal use only': 'Yes'} | G17: {} | H17: 4.3 | I17: (77 reviews) | J17: 530 W Grand Ave Elmhurst, IL 60126
A18: 2024 Chevrolet Blazer EV RS | B18: New | C18: 2,210 mi. | D18: $52,715MSRP $60,215 | E18: {'Exterior color': ' Summit White ', 'Interior color': 'Black ', 'Drivetrain': 'All-wheel Drive ', 'Transmission': '1-Speed Automatic', 'Engine': 'Electric', 'VIN': ' 3GNKDCRJ4RS113831 ', 'Stock #': ' V23091 ', 'Mileage': ' 2,210 mi. '} | F18: {} | G18: {} | H18: 4.1 | I18: (1,154 reviews) | J18: 400 E Roosevelt Rd Villa Park, IL 60181
A19: 2000 Jaguar XK8 | B19: Used | C19: 62,022 mi. | D19: 13995 | E19: {'Exterior color': ' Platinum Metallic ', 'Interior color': 'Ivory ', 'Drivetrain': 'Rear-wheel Drive ', 'MPG': ' 18â€“25Based on EPA mileage ratings. Use for comparison purposes only. Actual mileage will vary depending on driving conditions, driving habits, vehicle maintenance, and other factors.', 'Fuel type': 'Gasoline ', 'Transmission': '5-Speed Automatic', 'Engine': '4.0L V8 32V MPFI DOHC', 'VIN': ' SAJJA41CXYNA04688 ', 'Stock #': ' IA1389-NM ', 'Mileage': ' 62,022 mi. '} | F19: {'Accidents or damage': 'None reported', '1-owner vehicle': 'No', 'Personal use only': 'Yes'} | G19: {'Comfort': '4.0', 'Interior': '5.0', 'Performance': '3.0', 'Value': '3.0', 'Exterior': '5.0', 'Reliability': '3.0'} | J19: 594 W Lake St Elmhurst, IL 60126
A20: 2013 Subaru XV Crosstrek 2.0i Premium | B20: Used | C20: 84,358 mi. | D20: $13,900$1,000 price drop | E20: {'Exterior color': ' Venetian Red Pearl ', 'Interior color': 'Ivory ', 'Drivetrain': 'All-wheel Drive ', 'MPG': ' 25â€“33Based on EPA mileage ratings. Use for comparison purposes only. Actual mileage will vary depending on driving conditions, driving habits, vehicle maintenance, and other factors.', 'Fuel type': 'Gasoline ', 'Transmission': 'Automatic', 'Engine': '2L H-4 DOHC, variable valve control, regular unleaded, engine wi', 'VIN': ' JF2GPAVCXD2864679 ', 'Stock #': ' P5259 ', 'Mileage': ' 84,358 mi. '} | F20: {'Accidents or damage': 'At least 1 accident or damage reported', '1-owner vehicle': 'No', 'Personal use only': 'Yes', 'Open recall': 'At least 1 open recall reported'} | G20: {'Comfort': '4.0', 'Interior': '3.0', 'Performance': '1.0', 'Value': '1.0', 'Exterior': '4.0', 'Reliability': '1.0'} | H20: 4.8 | I20: (185 reviews) | J20: 12717 Cal Sag Rd Crestwood, IL 60445
A21: 2011 Ford E250 Cargo | B21: Used | C21: 181,000 mi. | D21: 9995 | E21: {'Exterior color': ' Red ', 'Interior color': 'Black ', 'Drivetrain': 'Rear-wheel Drive ', 'MPG': ' 13â€“17Based on EPA mileage ratings. Use for comparison purposes only. Actual mileage will vary depending on driving conditions, driving habits, vehicle maintenance, and other factors.', 'Fuel type': 'E85 Flex Fuel ', 'Transmission': '4-Speed Automatic', 'Engine': '5.4L V8 16V MPFI SOHC Flexible Fuel', 'VIN': ' 1FTNE2EL0BDA58661 ', 'Stock #': ' IA1399 ', 'Mileage': ' 181,000 mi. '} | F21: {'Accidents or damage': 'At least 1 accident or damage reported', '1-owner vehicle': 'No', 'Personal use only': 'No'} | G21: {} | J21: 594 W Lake St Elmhurst, IL 60126
A22: 2013 BMW 128 128i Coupe | B22: Used | C22: 77,783 mi. | D22: 8995 | E22: {'Exterior color': ' Pearl White ', 'Interior color': 'Black ', 'Drivetrain': 'Rear-wheel Drive ', 'MPG': ' 18â€“28Based on EPA mileage ratings. Use for comparison purposes only. Actual mileage will vary depending on driving conditions, driving habits, vehicle maintenance, and other factors.', 'Fuel type': 'Gasoline ', 'Transmission': 'Automatic', 'Engine': '3L I-6 DOHC, Double VANOS variable valve control, premium unlead', 'VIN': ' WBAUP9C59DVS95159 ', 'Stock #': ' TS-0538 ', 'Mileage': ' 77,783 mi. '} | F22: {'Accidents or damage': 'At least 1 accident or damage reported', '1-owner vehicle': 'No', 'Personal use only': 'Yes', 'Open recall': 'At least 1 open recall reported'} | G22: {} | J22: 13840 South Pulaski Road Crestwood, IL 60445
A23: 2019 Audi TTS 2.0T quattro | B23: Used | C23: 33,832 mi. | D23: $39,990$455 price drop | E23: {'Exterior color': ' Daytona Gray Pearl Effect ', 'Interior color': 'Black / Rock Gray ', 'Drivetrain': 'All-wheel Drive ', 'MPG': ' 23â€“29Based on EPA mileage ratings. Use for comparison purposes only. Actual mileage will vary depending on driving conditions, driving habits, vehicle maintenance, and other factors.', 'Fuel type': 'Gasoline ', 'Transmission': '7-Speed Automatic with Auto-Shift', 'Engine': '2.0L I4 16V GDI DOHC Turbo', 'VIN': ' TRUA1AFV2K1008212 ', 'Stock #': ' C1905A ', 'Mileage': ' 33,832 mi. '} | F23: {'Accidents or damage': 'None reported', '1-owner vehicle': 'Yes', 'Personal use only': 'Yes'} | G23: {'Comfort': '4.0', 'Interior': '5.0', 'Performance': '5.0', 'Value': '5.0', 'Exterior': '5.0', 'Reliability': '5.0'} | H23: 4.9 | I23: (2,168 reviews) | J23: 500 E. Ogden Ave. Westmont, IL 60559
A24: 1988 Chevrolet C10/K10 Base | B24: Used | C24: 48,934 mi. | D24: 19888 | E24: {'Exterior color': ' Barcelona Red ', 'Interior color': 'Barcelona Red ', 'Drivetrain': 'Rear-wheel Drive ', 'MPG': ' 0â€“0Based on EPA mileage ratings. Use for comparison purposes only. Actual mileage will vary depending on driving conditions, driving habits, vehicle maintenance, and other factors.', 'Fuel type': 'Gasoline ', 'Transmission': 'Automatic', 'Engine': '5.7 TBI V8', 'VIN': ' 1GCDC14K2JZ156418 ', 'Stock #': ' 156418 ', 'Mileage': ' 48,934 mi. '} | F24: {'Accidents or damage': 'None reported', '1-owner vehicle': 'No', 'Personal use only': 'No'} | G24: {} | H24: 5 | I24: (5 reviews) | J24: 1326 West Irving Park Road Bensenville, IL 60106
A25: 2016 Mercedes-Benz AMG G AMG G 63 4MATIC | B25: Used | C25: 59,386 mi. | D25: 71995 | E25: {'Exterior color': ' Palladium Silver Metallic ', 'Interior color': 'Designo Black ', 'Drivetrain': 'All-wheel Drive ', 'MPG': ' 12â€“14Based on EPA mileage ratings. Use for comparison purposes only. Actual mileage will vary depending on driving conditions, driving habits, vehicle maintenance, and other factors.', 'Fuel type': 'Gasoline ', 'Transmission': '7-Speed Automatic', 'Engine': '5.5L V8 32V GDI DOHC Twin Turbo', 'VIN': ' WDCYC7DF7GX258917 ', 'Stock #': ' HL7535 ', 'Mileage': ' 59,386 mi. '} | F25: {'Accidents or damage': 'At least 1 accident or damage reported', '1-owner vehicle': 'No', 'Personal use only': 'Yes'} | G25: {'Comfort': '5.0', 'Interior': '5.0', 'Performance': '5.0', 'Value': '5.0', 'Exterior': '5.0', 'Reliability': 'â€”'} | H25: 4.6 | I25: (358 reviews) | J25: 555 Executive Dr Willowbrook, IL 60527
A26: 2002 Lexus SC 430 Base | B26: Used | C26: 98,373 mi. | D26: $8,999$300 price drop | E26: {'Exterior color': ' Burgundy ', 'Interior color': 'Tan ', 'Drivetrain': 'Rear-wheel Drive ', 'MPG': ' 18â€“23Based on EPA mileage ratings. Use for comparison purposes only. Actual mileage will vary depending on driving conditions, driving habits, vehicle maintenance, and other factors.', 'Fuel type': 'Gasoline ', 'Transmission': 'Automatic', 'Engine': '4.3L (262) DOHC EFI 32-valve V8 aluminum engine-inc: continuousl', 'VIN': ' JTHFN48YX20002417 ', 'Stock #': ' YC-002417 ', 'Mileage': ' 98,373 mi. '} | F26: {'Accidents or damage': 'None reported', '1-owner vehicle': 'No', 'Personal use only': 'Yes'} | G26: {'Comfort': '5.0', 'Interior': '5.0', 'Performance': '4.0', 'Value': '5.0', 'Exterior': '5.0', 'Reliability': '5.0'} | H26: 4.3 | I26: (110 reviews) | J26: 3128 W 147th St Posen, IL 60469
A27: 2023 Lexus LC 500 Base | B27: New | C27: 0 mi. | D27: $106,615MSRP $114,420 | E27: {'Exterior color': ' Caviar ', 'Interior color': 'Red ', 'Drivetrain': 'Rear-wheel Drive ', 'MPG': ' 15â€“25Based on EPA mileage ratings. Use for comparison purposes only. Actual mileage will vary depending on driving conditions, driving habits, vehicle maintenance, and other factors.', 'Fuel type': 'Gasoline ', 'Transmission': '10-Speed Automatic', 'Engine': '5.0L V8 32V PDI DOHC', 'VIN': ' JTHMPAAY6PA107242 ', 'Stock #': ' B1781 ', 'Mileage': ' 0 mi. '} | F27: {} | G27: {} | H27: 4.9 | I27: (2,168 reviews) | J27: 500 E. Ogden Ave. Westmont, IL 60559
E28: {} | F28: {} | G28: {}
A29: 2006 Pontiac GTO | B29: Used | C29: 55,915 mi. | D29: $20,691$1,300 price drop | E29: {'Exterior color': ' Phantom Black Metallic ', 'Interior color': 'Red ', 'Drivetrain': 'Rear-wheel Drive ', 'MPG': ' â€“', 'Fuel type': 'Gasoline ', 'Transmission': '4-Speed Automatic', 'Engine': '6.0L V8 16V MPFI OHV', 'VIN': ' 6G2VX12U86L521103 ', 'Stock #': ' 6L521103 ', 'Mileage': ' 55,915 mi. '} | F29: {'Accidents or damage': 'At least 1 accident or damage reported', '1-owner vehicle': 'Yes', 'Personal use only': 'Yes'} | G29: {} | H29: 4.7 | I29: (1,955 reviews) | J29: 430 E. Ogden Ave. Westmont, IL 60559
A30: 1988 BMW M6 | B30: Used | C30: 46,344 mi. | D30: 63910 | E30: {'Exterior color': ' Cinnabar Red ', 'Interior color': 'Tan ', 'Drivetrain': 'Rear-wheel Drive ', 'MPG': ' â€“', 'Fuel type': 'Gasoline ', 'Transmission': '5-Speed Manual', 'Engine': '3.5L I6 24V DOHC', 'VIN': ' WBAEE1410J2561382 ', 'Stock #': ' C071421 ', 'Mileage': ' 46,344 mi. '} | F30: {'Accidents or damage': 'None reported', 'Clean title': 'Yes', '1-owner vehicle': 'No', 'Personal use only': 'Yes'} | G30: {} | H30: 3.9 | I30: (160 reviews) | J30: 100 W Ogden Ave Westmont, IL 60559
A31: 1975 Triumph TR6 | B31: Used | C31: 27,667 mi. | D31: 26507 | E31: {'Exterior color': ' Yellow ', 'Interior color': 'Black ', 'Drivetrain': 'â€“ ', 'MPG': ' â€“', 'Fuel type': 'â€“ ', 'Transmission': 'Manual', 'Engine': 'â€“', 'VIN': ' 000000000CF39098U ', 'Stock #': ' C040623-1 ', 'Mileage': ' 27,667 mi. '} | F31: {} | G31: {} | H31: 3.9 | I31: (160 reviews) | J31: 100 W Ogden Ave Westmont, IL 60559
A32: 2018 BMW M6 Base | B32: Used | C32: 46,698 mi. | D32: 45373 | E32: {'Exterior color': ' San Marino Blue Metallic ', 'Interior color': 'Black ', 'Drivetrain': 'Rear-wheel Drive ', 'MPG': ' 14â€“20Based on EPA mileage ratings. Use for comparison purposes only. Actual mileage will vary depending on driving conditions, driving habits, vehicle maintenance, and other factors.', 'Fuel type': 'Gasoline ', 'Transmission': '7-Speed Automatic', 'Engine': '4.4L V8 32V DOHC TwinPower Turbo', 'VIN': ' WBS6G9C59JBM23806 ', 'Stock #': ' UN4073 ', 'Mileage': ' 46,698 mi. '} | F32: {'Accidents or damage': 'None reported', '1-owner vehicle': 'No', 'Personal use only': 'Yes'} | G32: {'Comfort': '5.0', 'Interior': '5.0', 'Performance': '5.0', 'Value': '5.0', 'Exterior': '5.0', 'Reliability': '5.0'} | H32: 2.8 | I32: (83 reviews) | J32: 1850 Holste Rd Northbrook, IL 60062
A33: 2009 INFINITI G37 Journey | B33: Used | C33: 96,658 mi. | D33: 10980 | E33: {'Exterior color': ' Blue Slate Pearl ', 'Interior color': 'Beige ', 'Drivetrain': 'Rear-wheel Drive ', 'MPG': ' 18â€“26Based on EPA mileage ratings. Use for comparison purposes only. Actual mileage will vary depending on driving conditions, driving habits, vehicle maintenance, and other factors.', 'Fuel type': 'Gasoline ', 'Transmission': 'Automatic', 'Engine': 'VQ 3.7L V-6 DOHC, variable valve control, premium unleaded, engi', 'VIN': ' JNKCV64E49M606171 ', 'Stock #': ' 5963 ', 'Mileage': ' 96,658 mi. '} | F33: {'Accidents or damage': 'At least 1 accident or damage reported', 'Clean title': 'Yes', '1-owner vehicle': 'No', 'Personal use only': 'Yes'} | G33: {} | H33: 4.6 | I33: (189 reviews) | J33: 1886 S Elmhurst Rd Mt Prospect, IL 60056
A34: 2016 Volkswagen Golf SportWagen TSI SE | B34: Used | C34: 145,302 mi. | D34: 9495 | E34: {'Exterior color': ' Silver ', 'Interior color': 'Black ', 'Drivetrain': 'Front-wheel Drive ', 'MPG': ' 25â€“35Based on EPA mileage ratings. Use for comparison purposes only. Actual mileage will vary depending on driving conditions, driving habits, vehicle maintenance, and other factors.', 'Fuel type': 'Gasoline ', 'Transmission': '6-Speed Automatic', 'Engine': '1.8L I4 16V GDI DOHC Turbo', 'VIN': ' 3VWC17AU4GM509453 ', 'Stock #': ' XM651 ', 'Mileage': ' 145,302 mi. '} | F34: {'Accidents or damage': 'At least 1 accident or damage reported', '1-owner vehicle': 'No', 'Personal use only': 'Yes'} | G34: {'Comfort': '4.0', 'Interior': '5.0', 'Performance': '5.0', 'Value': '5.0', 'Exterior': '5.0', 'Reliability': '5.0'} | J34: 870 S Fiene Dr. Addison, IL 60101
A35: 2005 Scion xA Base (A4) | B35: Used | C35: 102,243 mi. | D35: 5795 | E35: {'Exterior color': ' Gray ', 'Interior color': 'Black ', 'Drivetrain': 'Front-wheel Drive ', 'MPG': ' 31â€“38Based on EPA mileage ratings. Use for comparison purposes only. Actual mileage will vary depending on driving conditions, driving habits, vehicle maintenance, and other factors.', 'Fuel type': 'Gasoline ', 'Transmission': '4-Speed Automatic', 'Engine': '1.5L I4 16V MPFI DOHC', 'VIN': ' JTKKT624450118605 ', 'Stock #': ' 2807 ', 'Mileage': ' 102,243 mi. '} | F35: {'Accidents or damage': 'At least 1 accident or damage reported', '1-owner vehicle': 'No', 'Personal use only': 'Yes'} | G35: {} | H35: 4.6 | I35: (50 reviews) | J35: 555 S IL Route 83 Elmhurst, IL 60126
A36: 2015 Toyota Prius v Three | B36: Used | C36: 91,655 mi. | D36: 13980 | E36: {'Exterior color': ' Attitude Black ', 'Interior color': 'Gray ', 'Drivetrain': 'Front-wheel Drive ', 'MPG': ' 44â€“40Based on EPA mileage ratings. Use for comparison purposes only. Actual mileage will vary depending on driving conditions, driving habits, vehicle maintenance, and other factors.', 'Fuel type': 'Gasoline ', 'Transmission': 'Automatic', 'Engine': '1.8L I-4 DOHC, VVT-i variable valve control, regular unleaded, e', 'VIN': ' JTDZN3EUXFJ016005 ', 'Stock #': ' 6069 ', 'Mileage': ' 91,655 mi. '} | F36: {'Accidents or damage': 'None reported', 'Clean title': 'Yes', '1-owner vehicle': 'No', 'Personal use only': 'Yes', 'Open recall': 'At least 1 open recall reported'} | G36: {'Comfort': '5.0', 'Interior': '5.0', 'Performance': '5.0', 'Value': '5.0', 'Exterior': '5.0', 'Reliability': '5.0'} | H36: 4.6 | I36: (189 reviews) | J36: 1886 S Elmhurst Rd Mt Prospect, IL 60056
A37: 2024 Mercedes-Benz AMG EQS Base | B37: New | C37: 6 mi. | D37: $152,800MSRP $152,800 | E37: {'Exterior color': ' Moonlight White ', 'Interior color': 'Black ', 'Drivetrain': 'All-wheel Drive ', 'Transmission': '1-Speed Automatic', 'Engine': 'Electric', 'VIN': ' W1KCG5FB6RA047125 ', 'Stock #': ' 64-592 ', 'Mileage': ' 6 mi. '} | F37: {} | G37: {} | H37: 4.7 | I37: (2,850 reviews) | J37: 1600 Frontage Rd Northbrook, IL 60062
A38: 2012 Toyota Prius v Two | B38: Used | C38: 168,725 mi. | D38: 9945 | E38: {'Exterior color': ' Magnetic Gray Metallic ', 'Interior color': 'GRAY ', 'Drivetrain': 'Front-wheel Drive ', 'MPG': ' 0â€“0Based on EPA mileage ratings. Use for comparison purposes only. Actual mileage will vary depending on driving conditions, driving habits, vehicle maintenance, and other factors.', 'Fuel type': 'Hybrid ', 'Transmission': 'Automatic', 'Engine': '1.8L 4 CYLINDER', 'VIN': ' JTDZN3EU5C3136231 ', 'Stock #': ' 36231 ', 'Mileage': ' 168,725 mi. '} | F38: {'Accidents or damage': 'None reported', '1-owner vehicle': 'Yes', 'Personal use only': 'Yes'} | G38: {'Comfort': '5.0', 'Interior': '5.0', 'Performance': '5.0', 'Value': '5.0', 'Exterior': '5.0', 'Reliability': 'â€”'} | H38: 4.2 | I38: (20 reviews) | J38: 350 S Lalonde Ave ADDISON, IL 60101
A39: 2008 Chrysler Sebring Touring | B39: Used | C39: 70,974 mi. | D39: 11950 | E39: {'Exterior color': ' Silver Steel Metallic Clearcoat ', 'Interior color': 'Dark Slate Gray/Light Slate Gray ', 'Drivetrain': 'Front-wheel Drive ', 'MPG': ' 18â€“26Based on EPA mileage ratings. Use for comparison purposes only. Actual mileage will vary depending on driving conditions, driving habits, vehicle maintenance, and other factors.', 'Fuel type': 'E85 Flex Fuel ', 'Transmission': 'Automatic', 'Engine': '2.7L V-6 DOHC, engine with 189HP', 'VIN': ' 1C3LC55R88N615598 ', 'Stock #': ' N615598 ', 'Mileage': ' 70,974 mi. '} | F39: {'Accidents or damage': 'None reported', '1-owner vehicle': 'No', 'Personal use only': 'Yes'} | G39: {} | H39: 4.6 | I39: (127 reviews) | J39: 1030 Republic Dr Addison, IL 60101
A40: 2007 Jeep Commander Sport | B40: Used | C40: 173,694 mi. | D40: $4,550$400 price drop | E40: {'Exterior color': ' Light Graystone Pearlcoat ', 'Interior color': 'Khaki ', 'Drivetrain': 'Four-wheel Drive ', 'MPG': ' 16â€“19Based on EPA mileage ratings. Use for comparison purposes only. Actual mileage will vary depending on driving conditions, driving habits, vehicle maintenance, and other factors.', 'Fuel type': 'Gasoline ', 'Transmission': 'Automatic', 'Engine': 'Power Tech 3.7L V-6 regular unleaded, engine with 210HP', 'VIN': ' 1J8HG48K37C510145 ', 'Stock #': ' B-329 ', 'Mileage': ' 173,694 mi. '} | F40: {'Accidents or damage': 'At least 1 accident or damage reported', 'Clean title': 'Yes', '1-owner vehicle': 'No', 'Personal use only': 'Yes'} | G40: {} | J40: 11S344 Jeans Road Lemont, IL 60439
...

Sheet Working Sheet
A1: Make | B1: Year | C1: Model | D1: Condition | E1: Mileage | F1: Final Cost | G1: Final | H1: Price Drop | I1: MSRP | J1: Basics Info | K1: Vehicle History Info | L1: Vehicle Reviews Info | M1: Seller Rating | N1: Seller Rating Count | O1: Seller Address
A2: Lexus | B2: 2024 | C2: LC 500 Base | D2: New | E2: 0 | F2: $112,865 | G2: $112,865 | H2: No | I2: MSRP $118,865 | J2: {'Exterior color': ' Caviar ', 'Interior color': 'Black ', 'Drivetrain': 'Rear-wheel Drive ', 'MPG': ' 15â€“25Based on EPA mileage ratings. Use for comparison purposes only. Actual mileage will vary depending on driving conditions, driving habits, vehicle maintenance, and other factors.', 'Fuel type': 'Gasoline ', 'Transmission': '10-Speed Automatic', 'Engine': '5.0L V8 32V PDI DOHC', 'VIN': ' JTHNPAAY2RA108024 ', 'Stock #': ' R087 ', 'Mileage': ' 0 mi. '} | K2: {} | L2: {} | M2: 4.7 | N2: (1,261 reviews) | O2: 1250 W Division St Chicago, IL 60642
A3: Acura | B3: 2007 | C3: TSX Base | D3: Used | E3: 61110 | F3: 11295 | G3: 11295 | H3: No | J3: {'Exterior color': ' Alabaster Silver Metallic ', 'Interior color': 'â€“ ', 'Drivetrain': 'Front-wheel Drive ', 'MPG': ' 22â€“31Based on EPA mileage ratings. Use for comparison purposes only. Actual mileage will vary depending on driving conditions, driving habits, vehicle maintenance, and other factors.', 'Fuel type': 'Gasoline ', 'Transmission': 'Automatic', 'Engine': '2.4L I-4 DOHC, i-VTEC variable valve control, premium unleaded,', 'VIN': ' JH4CL96827C013765 ', 'Stock #': ' A40896A ', 'Mileage': ' 61,110 mi. '} | K3: {'Accidents or damage': 'At least 1 accident or damage reported', '1-owner vehicle': 'Yes', 'Personal use only': 'Yes'} | L3: {} | M3: 4.2 | N3: (440 reviews) | O3: 1301 N Elston Ave Chicago, IL 60642
A4: McLaren | B4: 2016 | C4: 675LT Base | D4: Used | E4: 6305 | F4: $219,997$5,464 | G4: $219,997 | H4: Yes | J4: {'Exterior color': ' McLaren Orange ', 'Interior color': 'Carbon Black ', 'Drivetrain': 'Rear-wheel Drive ', 'MPG': ' â€“', 'Fuel type': 'Gasoline ', 'Transmission': '7-Speed Automatic with Auto-Shift', 'Engine': '3.8L V8 32V MPFI DOHC Twin Turbo', 'VIN': ' SBM11RAA7GW675095 ', 'Stock #': ' K2338 ', 'Mileage': ' 6,305 mi. '} | K4: {'Accidents or damage': 'At least 1 accident or damage reported', '1-owner vehicle': 'No', 'Personal use only': 'No'} | L4: {'Comfort': '5.0', 'Interior': '5.0', 'Performance': '5.0', 'Value': '5.0', 'Exterior': '5.0', 'Reliability': '5.0'} | M4: 3.1 | N4: (421 reviews) | O4: 1561 N Fremont St Chicago, IL 60642
A5: Audi | B5: 2016 | C5: TTS 2.0T quattro | D5: Used | E5: 65715 | F5: 23999 | G5: 23999 | H5: No | J5: {'Exterior color': ' Black ', 'Interior color': 'Black ', 'Drivetrain': 'All-wheel Drive ', 'MPG': ' 23â€“27Based on EPA mileage ratings. Use for comparison purposes only. Actual mileage will vary depending on driving conditions, driving habits, vehicle maintenance, and other factors.', 'Fuel type': 'Gasoline ', 'Transmission': '6-Speed Automatic with Auto-Shift', 'Engine': '2.0L I4 16V GDI DOHC Turbo', 'VIN': ' TRUC1AFV1G1019119 ', 'Stock #': ' 3949 ', 'Mileage': ' 65,715 mi. '} | K5: {'Accidents or damage': 'At least 1 accident or damage reported', 'Clean title': 'Yes', '1-owner vehicle': 'No', 'Personal use only': 'Yes'} | L5: {'Comfort': '3.0', 'Interior': '5.0', 'Performance': '5.0', 'Value': '5.0', 'Exterior': '5.0', 'Reliability': '5.0'} | M5: 3.6 | N5: (123 reviews) | O5: 560 E North Ave West Chicago, IL 60185
A6: BMW | B6: 2018 | C6: 740e xDrive iPerformance | D6: Used | E6: 19830 | F6: $39,799$100 | G6: $39,799 | H6: Yes | J6: {'Exterior color': ' Imperial Blue Metallic ', 'Interior color': 'Black ', 'Drivetrain': 'All-wheel Drive ', 'MPG': ' 0â€“0Based on EPA mileage ratings. Use for comparison purposes only. Actual mileage will vary depending on driving conditions, driving habits, vehicle maintenance, and other factors.', 'Fuel type': 'Gasoline ', 'Transmission': '8-Speed Automatic', 'Engine': '2L I-4 gasoline direct injection, DOHC, Double VANOS variable va', 'VIN': ' WBA7J2C57JG938534 ', 'Stock #': ' A6006 ', 'Mileage': ' 19,830 mi. '} | K6: {'Accidents or damage': 'None reported', 'Clean title': 'Yes', '1-owner vehicle': 'Yes', 'Personal use only': 'No'} | L6: {'Comfort': '5.0', 'Interior': '5.0', 'Performance': '5.0', 'Value': '5.0', 'Exterior': '5.0', 'Reliability': '5.0'} | M6: 4.4 | N6: (91 reviews) | O6: 6539 Ogden Ave Berwyn, IL 60402
A7: Jeep | B7: 2019 | C7: Cherokee Limited | D7: Used | E7: 52245 | F7: $22,966$173 | G7: $22,966 | H7: Yes | J7: {'Exterior color': ' Diamond Black ', 'Interior color': 'Black ', 'Drivetrain': 'Four-wheel Drive ', 'MPG': ' 19â€“27Based on EPA mileage ratings. Use for comparison purposes only. Actual mileage will vary depending on driving conditions, driving habits, vehicle maintenance, and other factors.', 'Fuel type': 'Gasoline ', 'Transmission': '9-Speed Automatic', 'Engine': '3.2L V6 24V MPFI DOHC', 'VIN': ' 1C4PJMDX4KD139201 ', 'Stock #': ' Y17217A ', 'Mileage': ' 52,245 mi. '} | K7: {'Accidents or damage': 'At least 1 accident or damage reported', '1-owner vehicle': 'No', 'Personal use only': 'No'} | L7: {} | M7: 4.2 | N7: (3,030 reviews) | O7: 6750 W Grand Ave Chicago, IL 60707
A8: Cadillac | B8: 2019 | C8: CT6 3.6L Luxury | D8: Used | E8: 94008 | F8: $26,995$183 | G8: $26,995 | H8: Yes | J8: {'Exterior color': ' Black ', 'Interior color': 'Black ', 'Drivetrain': 'All-wheel Drive ', 'MPG': ' 18â€“27Based on EPA mileage ratings. Use for comparison purposes only. Actual mileage will vary depending on driving conditions, driving habits, vehicle maintenance, and other factors.', 'Fuel type': 'Gasoline ', 'Transmission': 'Automatic', 'Engine': '3.6L V-6 gasoline direct injection, DOHC, VVT variable valve con', 'VIN': ' 1G6KB5RS1KU131814 ', 'Stock #': ' 8378 ', 'Mileage': ' 94,008 mi. '} | K8: {'Accidents or damage': 'At least 1 accident or damage reported', '1-owner vehicle': 'No', 'Personal use only': 'No'} | L8: {} | M8: 4.1 | N8: (50 reviews) | O8: 7158 Harlem Ave Bridgeview, IL 60455
A9: Nissan | B9: 2012 | C9: NV Cargo S | D9: Used | E9: 110202 | F9: 14985 | G9: 14985 | H9: No | J9: {'Exterior color': ' Blizzard ', 'Interior color': 'Gray ', 'Drivetrain': 'Rear-wheel Drive ', 'MPG': ' â€“', 'Fuel type': 'Gasoline ', 'Transmission': 'Automatic', 'Engine': '5.6L V8 32V MPFI DOHC', 'VIN': ' 1N6AF0KX9CN103838 ', 'Stock #': ' 8418 ', 'Mileage': ' 110,202 mi. '} | K9: {'Accidents or damage': 'At least 1 accident or damage reported', 'Clean title': 'Yes', '1-owner vehicle': 'No', 'Personal use only': 'No'} | L9: {'Comfort': '5.0', 'Interior': '5.0', 'Performance': '5.0', 'Value': '4.0', 'Exterior': '4.0', 'Reliability': '3.0'} | M9: 3.6 | N9: (64 reviews) | O9: 6007 S Archer Rd Summit, IL 60501
A10: Chrysler | B10: 2008 | C10: Sebring Touring | D10: Used | E10: 77893 | F10: 7995 | G10: 7995 | H10: No | J10: {'Exterior color': ' Silver ', 'Interior color': 'Gray ', 'Drivetrain': 'Front-wheel Drive ', 'MPG': ' 26â€“26Based on EPA mileage ratings. Use for comparison purposes only. Actual mileage will vary depending on driving conditions, driving habits, vehicle maintenance, and other factors.', 'Fuel type': 'E85 Flex Fuel ', 'Transmission': 'Automatic 4-Speed', 'Engine': '2.7L V6', 'VIN': ' 1C3LC55R58N689769 ', 'Stock #': ' 8N689769STK ', 'Mileage': ' 77,893 mi. '} | K10: {'Accidents or damage': 'None reported', '1-owner vehicle': 'No', 'Personal use only': 'Yes'} | L10: {} | M10: 3.5 | N10: (43 reviews) | O10: 1210 25th Ave Melrose Park, IL 60160
A11: Ford | B11: 2012 | C11: E250 Cargo | D11: Used | E11: 106430 | F11: $15,750$540 | G11: $15,750 | H11: Yes | J11: {'Exterior color': ' White ', 'Interior color': 'Gray ', 'Drivetrain': 'Rear-wheel Drive ', 'MPG': ' 17â€“17Based on EPA mileage ratings. Use for comparison purposes only. Actual mileage will vary depending on driving conditions, driving habits, vehicle maintenance, and other factors.', 'Fuel type': 'E85 Flex Fuel ', 'Transmission': 'Automatic 4-Speed', 'Engine': '4.6L V8', 'VIN': ' 1FTNE2EW9CDA52319 ', 'Stock #': ' T0137 ', 'Mileage': ' 106,430 mi. '} | K11: {'Accidents or damage': 'None reported', 'Clean title': 'No', '1-owner vehicle': 'No', 'Personal use only': 'No'} | L11: {'Comfort': '4.0', 'Interior': '4.0', 'Performance': '4.0', 'Value': '5.0', 'Exterior': '4.0', 'Reliability': '5.0'} | O11: 6400 Harlem Ave Summit, IL 60501
A12: Toyota | B12: 2013 | C12: Prius v Five | D12: Used | E12: 155600 | F12: 12995 | G12: 12995 | H12: No | J12: {'Exterior color': ' Blue ', 'Interior color': 'Gray ', 'Drivetrain': 'Front-wheel Drive ', 'MPG': ' 44â€“40Based on EPA mileage ratings. Use for comparison purposes only. Actual mileage will vary depending on driving conditions, driving habits, vehicle maintenance, and other factors.', 'Fuel type': 'Gasoline ', 'Transmission': 'Automatic', 'Engine': '1.8L I-4 DOHC, VVT-i variable valve control, regular unleaded, e', 'VIN': ' JTDZN3EU9D3206492 ', 'Stock #': ' GA-206492 ', 'Mileage': ' 155,600 mi. '} | K12: {'Accidents or damage': 'At least 1 accident or damage reported', '1-owner vehicle': 'No', 'Personal use only': 'Yes'} | L12: {'Comfort': '5.0', 'Interior': '4.0', 'Performance': '4.0', 'Value': '5.0', 'Exterior': '4.0', 'Reliability': '5.0'} | O12: 5050 Dempster Street Skokie, IL 60077
A13: BMW | B13: 2002 | C13: 745 Li | D13: Used | E13: 146000 | F13: 4599 | G13: 4599 | H13: No | J13: {'Exterior color': ' White ', 'Interior color': 'Beige ', 'Drivetrain': 'Rear-wheel Drive ', 'Fuel type': 'Gasoline ', 'Transmission': 'A/T', 'Engine': '325.0HP 4.4L 8 Cylinder Engine Gasoline Fuel', 'VIN': ' WBAGN634X2DR03993 ', 'Mileage': ' 146,000 mi. '} | K13: {'Accidents or damage': 'None reported', 'Clean title': 'Yes', '1-owner vehicle': 'No', 'Personal use only': 'Yes'} | L13: {}
A14: INFINITI | B14: 2020 | C14: Q60 3.0t Red Sport 400 | D14: Used | E14: 22901 | F14: 38713 | G14: 38713 | H14: No | J14: {'Exterior color': ' Iridium Blue ', 'Interior color': 'Blue ', 'Drivetrain': 'Rear-wheel Drive ', 'MPG': ' 20â€“27Based on EPA mileage ratings. Use for comparison purposes only. Actual mileage will vary depending on driving conditions, driving habits, vehicle maintenance, and other factors.', 'Fuel type': 'Gasoline ', 'Transmission': '7-Speed Automatic', 'Engine': '3.0L V6 24V GDI DOHC Twin Turbo', 'VIN': ' JN1FV7EK1LM400180 ', 'Stock #': ' M91221 ', 'Mileage': ' 22,901 mi. '} | K14: {'Accidents or damage': 'None reported', '1-owner vehicle': 'Yes', 'Personal use only': 'Yes'} | L14: {} | M14: 4.1 | N14: (591 reviews) | O14: 6750 West 95th Street Oak Lawn, IL 60453
A15: Volkswagen | B15: 2014 | C15: Beetle 1.8T | D15: Used | E15: 48650 | F15: 16988 | G15: 16988 | H15: No | J15: {'Exterior color': ' Platinum Gray Metallic ', 'Interior color': 'Titan Black ', 'Drivetrain': 'Front-wheel Drive ', 'MPG': ' 25â€“33Based on EPA mileage ratings. Use for comparison purposes only. Actual mileage will vary depending on driving conditions, driving habits, vehicle maintenance, and other factors.', 'Fuel type': 'Gasoline ', 'Transmission': '6-Speed Automatic', 'Engine': '1.8L I4 16V GDI DOHC Turbo', 'VIN': ' 3VWJ17AT3EM659954 ', 'Stock #': ' P7459VW ', 'Mileage': ' 48,650 mi. '} | K15: {'Accidents or damage': 'None reported', '1-owner vehicle': 'Yes', 'Personal use only': 'Yes'} | L15: {} | M15: 4.5 | N15: (1,555 reviews) | O15: 241 Waukegan Rd Glenview, IL 60025
A16: BMW | B16: 2015 | C16: M235 i | D16: Used | E16: 73660 | F16: 22843 | G16: 22843 | H16: No | J16: {'Exterior color': ' Glacier Silver Metallic ', 'Interior color': 'â€“ ', 'Drivetrain': 'Rear-wheel Drive ', 'MPG': ' 21â€“32Based on EPA mileage ratings. Use for comparison purposes only. Actual mileage will vary depending on driving conditions, driving habits, vehicle maintenance, and other factors.', 'Fuel type': 'Gasoline ', 'Transmission': '8-Speed Automatic', 'Engine': '3.0L I6 24V GDI DOHC Turbo', 'VIN': ' WBA1J7C59FV358577 ', 'Stock #': ' R6301 ', 'Mileage': ' 73,660 mi. '} | K16: {'Accidents or damage': 'None reported', 'Clean title': 'Yes', '1-owner vehicle': 'No', 'Personal use only': 'Yes'} | L16: {} | M16: 4 | N16: (288 reviews) | O16: 11201 S Harlem Ave Worth, IL 60482
A17: BMW | B17: 2004 | C17: 745 745i | D17: Used | E17: 119263 | F17: 7999 | G17: 7999 | H17: No | J17: {'Exterior color': ' Gold ', 'Interior color': 'Tan ', 'Drivetrain': 'Rear-wheel Drive ', 'MPG': ' 18â€“26Based on EPA mileage ratings. Use for comparison purposes only. Actual mileage will vary depending on driving conditions, driving habits, vehicle maintenance, and other factors.', 'Fuel type': 'Gasoline ', 'Transmission': '6-speed Steptronic automatic transmission w/OD-inc', 'Engine': '4.4L (268) DOHC EFI 32-valve aluminum V8 engine w/variable valve', 'VIN': ' WBAGL63424DP69960 ', 'Stock #': ' EM-P69960 ', 'Mileage': ' 119,263 mi. '} | K17: {'Accidents or damage': 'None reported', '1-owner vehicle': 'No', 'Personal use only': 'Yes'} | L17: {} | M17: 4.3 | N17: (77 reviews) | O17: 530 W Grand Ave Elmhurst, IL 60126
A18: Chevrolet | B18: 2024 | C18: Blazer EV RS | D18: New | E18: 2210 | F18: $52,715 | G18: $52,715 | H18: No | I18: MSRP $60,215 | J18: {'Exterior color': ' Summit White ', 'Interior color': 'Black ', 'Drivetrain': 'All-wheel Drive ', 'Transmission': '1-Speed Automatic', 'Engine': 'Electric', 'VIN': ' 3GNKDCRJ4RS113831 ', 'Stock #': ' V23091 ', 'Mileage': ' 2,210 mi. '} | K18: {} | L18: {} | M18: 4.1 | N18: (1,154 reviews) | O18: 400 E Roosevelt Rd Villa Park, IL 60181
A19: Jaguar | B19: 2000 | C19: XK8 | D19: Used | E19: 62022 | F19: 13995 | G19: 13995 | H19: No | J19: {'Exterior color': ' Platinum Metallic ', 'Interior color': 'Ivory ', 'Drivetrain': 'Rear-wheel Drive ', 'MPG': ' 18â€“25Based on EPA mileage ratings. Use for comparison purposes only. Actual mileage will vary depending on driving conditions, driving habits, vehicle maintenance, and other factors.', 'Fuel type': 'Gasoline ', 'Transmission': '5-Speed Automatic', 'Engine': '4.0L V8 32V MPFI DOHC', 'VIN': ' SAJJA41CXYNA04688 ', 'Stock #': ' IA1389-NM ', 'Mileage': ' 62,022 mi. '} | K19: {'Accidents or damage': 'None reported', '1-owner vehicle': 'No', 'Personal use only': 'Yes'} | L19: {'Comfort': '4.0', 'Interior': '5.0', 'Performance': '3.0', 'Value': '3.0', 'Exterior': '5.0', 'Reliability': '3.0'} | O19: 594 W Lake St Elmhurst, IL 60126
A20: Subaru | B20: 2013 | C20: XV Crosstrek 2.0i Premium | D20: Used | E20: 84358 | F20: $13,900$1,000 | G20: $13,900 | H20: Yes | J20: {'Exterior color': ' Venetian Red Pearl ', 'Interior color': 'Ivory ', 'Drivetrain': 'All-wheel Drive ', 'MPG': ' 25â€“33Based on EPA mileage ratings. Use for comparison purposes only. Actual mileage will vary depending on driving conditions, driving habits, vehicle maintenance, and other factors.', 'Fuel type': 'Gasoline ', 'Transmission': 'Automatic', 'Engine': '2L H-4 DOHC, variable valve control, regular unleaded, engine wi', 'VIN': ' JF2GPAVCXD2864679 ', 'Stock #': ' P5259 ', 'Mileage': ' 84,358 mi. '} | K20: {'Accidents or damage': 'At least 1 accident or damage reported', '1-owner vehicle': 'No', 'Personal use only': 'Yes', 'Open recall': 'At least 1 open recall reported'} | L20: {'Comfort': '4.0', 'Interior': '3.0', 'Performance': '1.0', 'Value': '1.0', 'Exterior': '4.0', 'Reliability': '1.0'} | M20: 4.8 | N20: (185 reviews) | O20: 12717 Cal Sag Rd Crestwood, IL 60445
A21: Ford | B21: 2011 | C21: E250 Cargo | D21: Used | E21: 181000 | F21: 9995 | G21: 9995 | H21: No | J21: {'Exterior color': ' Red ', 'Interior color': 'Black ', 'Drivetrain': 'Rear-wheel Drive ', 'MPG': ' 13â€“17Based on EPA mileage ratings. Use for comparison purposes only. Actual mileage will vary depending on driving conditions, driving habits, vehicle maintenance, and other factors.', 'Fuel type': 'E85 Flex Fuel ', 'Transmission': '4-Speed Automatic', 'Engine': '5.4L V8 16V MPFI SOHC Flexible Fuel', 'VIN': ' 1FTNE2EL0BDA58661 ', 'Stock #': ' IA1399 ', 'Mileage': ' 181,000 mi. '} | K21: {'Accidents or damage': 'At least 1 accident or damage reported', '1-owner vehicle': 'No', 'Personal use only': 'No'} | L21: {} | O21: 594 W Lake St Elmhurst, IL 60126
A22: BMW | B22: 2013 | C22: 128 128i Coupe | D22: Used | E22: 77783 | F22: 8995 | G22: 8995 | H22: No | J22: {'Exterior color': ' Pearl White ', 'Interior color': 'Black ', 'Drivetrain': 'Rear-wheel Drive ', 'MPG': ' 18â€“28Based on EPA mileage ratings. Use for comparison purposes only. Actual mileage will vary depending on driving conditions, driving habits, vehicle maintenance, and other factors.', 'Fuel type': 'Gasoline ', 'Transmission': 'Automatic', 'Engine': '3L I-6 DOHC, Double VANOS variable valve control, premium unlead', 'VIN': ' WBAUP9C59DVS95159 ', 'Stock #': ' TS-0538 ', 'Mileage': ' 77,783 mi. '} | K22: {'Accidents or damage': 'At least 1 accident or damage reported', '1-owner vehicle': 'No', 'Personal use only': 'Yes', 'Open recall': 'At least 1 open recall reported'} | L22: {} | O22: 13840 South Pulaski Road Crestwood, IL 60445
A23: Audi | B23: 2019 | C23: TTS 2.0T quattro | D23: Used | E23: 33832 | F23: $39,990$455 | G23: $39,990 | H23: Yes | J23: {'Exterior color': ' Daytona Gray Pearl Effect ', 'Interior color': 'Black / Rock Gray ', 'Drivetrain': 'All-wheel Drive ', 'MPG': ' 23â€“29Based on EPA mileage ratings. Use for comparison purposes only. Actual mileage will vary depending on driving conditions, driving habits, vehicle maintenance, and other factors.', 'Fuel type': 'Gasoline ', 'Transmission': '7-Speed Automatic with Auto-Shift', 'Engine': '2.0L I4 16V GDI DOHC Turbo', 'VIN': ' TRUA1AFV2K1008212 ', 'Stock #': ' C1905A ', 'Mileage': ' 33,832 mi. '} | K23: {'Accidents or damage': 'None reported', '1-owner vehicle': 'Yes', 'Personal use only': 'Yes'} | L23: {'Comfort': '4.0', 'Interior': '5.0', 'Performance': '5.0', 'Value': '5.0', 'Exterior': '5.0', 'Reliability': '5.0'} | M23: 4.9 | N23: (2,168 reviews) | O23: 500 E. Ogden Ave. Westmont, IL 60559
A24: Chevrolet | B24: 1988 | C24: C10/K10 Base | D24: Used | E24: 48934 | F24: 19888 | G24: 19888 | H24: No | J24: {'Exterior color': ' Barcelona Red ', 'Interior color': 'Barcelona Red ', 'Drivetrain': 'Rear-wheel Drive ', 'MPG': ' 0â€“0Based on EPA mileage ratings. Use for comparison purposes only. Actual mileage will vary depending on driving conditions, driving habits, vehicle maintenance, and other factors.', 'Fuel type': 'Gasoline ', 'Transmission': 'Automatic', 'Engine': '5.7 TBI V8', 'VIN': ' 1GCDC14K2JZ156418 ', 'Stock #': ' 156418 ', 'Mileage': ' 48,934 mi. '} | K24: {'Accidents or damage': 'None reported', '1-owner vehicle': 'No', 'Personal use only': 'No'} | L24: {} | M24: 5 | N24: (5 reviews) | O24: 1326 West Irving Park Road Bensenville, IL 60106
A25: Mercedes-Benz | B25: 2016 | C25: AMG G AMG G 63 4MATIC | D25: Used | E25: 59386 | F25: 71995 | G25: 71995 | H25: No | J25: {'Exterior color': ' Palladium Silver Metallic ', 'Interior color': 'Designo Black ', 'Drivetrain': 'All-wheel Drive ', 'MPG': ' 12â€“14Based on EPA mileage ratings. Use for comparison purposes only. Actual mileage will vary depending on driving conditions, driving habits, vehicle maintenance, and other factors.', 'Fuel type': 'Gasoline ', 'Transmission': '7-Speed Automatic', 'Engine': '5.5L V8 32V GDI DOHC Twin Turbo', 'VIN': ' WDCYC7DF7GX258917 ', 'Stock #': ' HL7535 ', 'Mileage': ' 59,386 mi. '} | K25: {'Accidents or damage': 'At least 1 accident or damage reported', '1-owner vehicle': 'No', 'Personal use only': 'Yes'} | L25: {'Comfort': '5.0', 'Interior': '5.0', 'Performance': '5.0', 'Value': '5.0', 'Exterior': '5.0', 'Reliability': 'â€”'} | M25: 4.6 | N25: (358 reviews) | O25: 555 Executive Dr Willowbrook, IL 60527
A26: Lexus | B26: 2002 | C26: SC 430 Base | D26: Used | E26: 98373 | F26: $8,999$300 | G26: $8,999 | H26: Yes | J26: {'Exterior color': ' Burgundy ', 'Interior color': 'Tan ', 'Drivetrain': 'Rear-wheel Drive ', 'MPG': ' 18â€“23Based on EPA mileage ratings. Use for comparison purposes only. Actual mileage will vary depending on driving conditions, driving habits, vehicle maintenance, and other factors.', 'Fuel type': 'Gasoline ', 'Transmission': 'Automatic', 'Engine': '4.3L (262) DOHC EFI 32-valve V8 aluminum engine-inc: continuousl', 'VIN': ' JTHFN48YX20002417 ', 'Stock #': ' YC-002417 ', 'Mileage': ' 98,373 mi. '} | K26: {'Accidents or damage': 'None reported', '1-owner vehicle': 'No', 'Personal use only': 'Yes'} | L26: {'Comfort': '5.0', 'Interior': '5.0', 'Performance': '4.0', 'Value': '5.0', 'Exterior': '5.0', 'Reliability': '5.0'} | M26: 4.3 | N26: (110 reviews) | O26: 3128 W 147th St Posen, IL 60469
A27: Lexus | B27: 2023 | C27: LC 500 Base | D27: New | E27: 0 | F27: $106,615 | G27: $106,615 | H27: No | I27: MSRP $114,420 | J27: {'Exterior color': ' Caviar ', 'Interior color': 'Red ', 'Drivetrain': 'Rear-wheel Drive ', 'MPG': ' 15â€“25Based on EPA mileage ratings. Use for comparison purposes only. Actual mileage will vary depending on driving conditions, driving habits, vehicle maintenance, and other factors.', 'Fuel type': 'Gasoline ', 'Transmission': '10-Speed Automatic', 'Engine': '5.0L V8 32V PDI DOHC', 'VIN': ' JTHMPAAY6PA107242 ', 'Stock #': ' B1781 ', 'Mileage': ' 0 mi. '} | K27: {} | L27: {} | M27: 4.9 | N27: (2,168 reviews) | O27: 500 E. Ogden Ave. Westmont, IL 60559
C28: 0 | F28: 0 | G28: 0 | H28: No | J28: {} | K28: {} | L28: {}
A29: Pontiac | B29: 2006 | C29: GTO | D29: Used | E29: 55915 | F29: $20,691$1,300 | G29: $20,691 | H29: Yes | J29: {'Exterior color': ' Phantom Black Metallic ', 'Interior color': 'Red ', 'Drivetrain': 'Rear-wheel Drive ', 'MPG': ' â€“', 'Fuel type': 'Gasoline ', 'Transmission': '4-Speed Automatic', 'Engine': '6.0L V8 16V MPFI OHV', 'VIN': ' 6G2VX12U86L521103 ', 'Stock #': ' 6L521103 ', 'Mileage': ' 55,915 mi. '} | K29: {'Accidents or damage': 'At least 1 accident or damage reported', '1-owner vehicle': 'Yes', 'Personal use only': 'Yes'} | L29: {} | M29: 4.7 | N29: (1,955 reviews) | O29: 430 E. Ogden Ave. Westmont, IL 60559
A30: BMW | B30: 1988 | C30: M6 | D30: Used | E30: 46344 | F30: 63910 | G30: 63910 | H30: No | J30: {'Exterior color': ' Cinnabar Red ', 'Interior color': 'Tan ', 'Drivetrain': 'Rear-wheel Drive ', 'MPG': ' â€“', 'Fuel type': 'Gasoline ', 'Transmission': '5-Speed Manual', 'Engine': '3.5L I6 24V DOHC', 'VIN': ' WBAEE1410J2561382 ', 'Stock #': ' C071421 ', 'Mileage': ' 46,344 mi. '} | K30: {'Accidents or damage': 'None reported', 'Clean title': 'Yes', '1-owner vehicle': 'No', 'Personal use only': 'Yes'} | L30: {} | M30: 3.9 | N30: (160 reviews) | O30: 100 W Ogden Ave Westmont, IL 60559
A31: Triumph | B31: 1975 | C31: TR6 | D31: Used | E31: 27667 | F31: 26507 | G31: 26507 | H31: No | J31: {'Exterior color': ' Yellow ', 'Interior color': 'Black ', 'Drivetrain': 'â€“ ', 'MPG': ' â€“', 'Fuel type': 'â€“ ', 'Transmission': 'Manual', 'Engine': 'â€“', 'VIN': ' 000000000CF39098U ', 'Stock #': ' C040623-1 ', 'Mileage': ' 27,667 mi. '} | K31: {} | L31: {} | M31: 3.9 | N31: (160 reviews) | O31: 100 W Ogden Ave Westmont, IL 60559
A32: BMW | B32: 2018 | C32: M6 Base | D32: Used | E32: 46698 | F32: 45373 | G32: 45373 | H32: No | J32: {'Exterior color': ' San Marino Blue Metallic ', 'Interior color': 'Black ', 'Drivetrain': 'Rear-wheel Drive ', 'MPG': ' 14â€“20Based on EPA mileage ratings. Use for comparison purposes only. Actual mileage will vary depending on driving conditions, driving habits, vehicle maintenance, and other factors.', 'Fuel type': 'Gasoline ', 'Transmission': '7-Speed Automatic', 'Engine': '4.4L V8 32V DOHC TwinPower Turbo', 'VIN': ' WBS6G9C59JBM23806 ', 'Stock #': ' UN4073 ', 'Mileage': ' 46,698 mi. '} | K32: {'Accidents or damage': 'None reported', '1-owner vehicle': 'No', 'Personal use only': 'Yes'} | L32: {'Comfort': '5.0', 'Interior': '5.0', 'Performance': '5.0', 'Value': '5.0', 'Exterior': '5.0', 'Reliability': '5.0'} | M32: 2.8 | N32: (83 reviews) | O32: 1850 Holste Rd Northbrook, IL 60062
A33: INFINITI | B33: 2009 | C33: G37 Journey | D33: Used | E33: 96658 | F33: 10980 | G33: 10980 | H33: No | J33: {'Exterior color': ' Blue Slate Pearl ', 'Interior color': 'Beige ', 'Drivetrain': 'Rear-wheel Drive ', 'MPG': ' 18â€“26Based on EPA mileage ratings. Use for comparison purposes only. Actual mileage will vary depending on driving conditions, driving habits, vehicle maintenance, and other factors.', 'Fuel type': 'Gasoline ', 'Transmission': 'Automatic', 'Engine': 'VQ 3.7L V-6 DOHC, variable valve control, premium unleaded, engi', 'VIN': ' JNKCV64E49M606171 ', 'Stock #': ' 5963 ', 'Mileage': ' 96,658 mi. '} | K33: {'Accidents or damage': 'At least 1 accident or damage reported', 'Clean title': 'Yes', '1-owner vehicle': 'No', 'Personal use only': 'Yes'} | L33: {} | M33: 4.6 | N33: (189 reviews) | O33: 1886 S Elmhurst Rd Mt Prospect, IL 60056
A34: Volkswagen | B34: 2016 | C34: Golf SportWagen TSI SE | D34: Used | E34: 145302 | F34: 9495 | G34: 9495 | H34: No | J34: {'Exterior color': ' Silver ', 'Interior color': 'Black ', 'Drivetrain': 'Front-wheel Drive ', 'MPG': ' 25â€“35Based on EPA mileage ratings. Use for comparison purposes only. Actual mileage will vary depending on driving conditions, driving habits, vehicle maintenance, and other factors.', 'Fuel type': 'Gasoline ', 'Transmission': '6-Speed Automatic', 'Engine': '1.8L I4 16V GDI DOHC Turbo', 'VIN': ' 3VWC17AU4GM509453 ', 'Stock #': ' XM651 ', 'Mileage': ' 145,302 mi. '} | K34: {'Accidents or damage': 'At least 1 accident or damage reported', '1-owner vehicle': 'No', 'Personal use only': 'Yes'} | L34: {'Comfort': '4.0', 'Interior': '5.0', 'Performance': '5.0', 'Value': '5.0', 'Exterior': '5.0', 'Reliability': '5.0'} | O34: 870 S Fiene Dr. Addison, IL 60101
A35: Scion | B35: 2005 | C35: xA Base (A4) | D35: Used | E35: 102243 | F35: 5795 | G35: 5795 | H35: No | J35: {'Exterior color': ' Gray ', 'Interior color': 'Black ', 'Drivetrain': 'Front-wheel Drive ', 'MPG': ' 31â€“38Based on EPA mileage ratings. Use for comparison purposes only. Actual mileage will vary depending on driving conditions, driving habits, vehicle maintenance, and other factors.', 'Fuel type': 'Gasoline ', 'Transmission': '4-Speed Automatic', 'Engine': '1.5L I4 16V MPFI DOHC', 'VIN': ' JTKKT624450118605 ', 'Stock #': ' 2807 ', 'Mileage': ' 102,243 mi. '} | K35: {'Accidents or damage': 'At least 1 accident or damage reported', '1-owner vehicle': 'No', 'Personal use only': 'Yes'} | L35: {} | M35: 4.6 | N35: (50 reviews) | O35: 555 S IL Route 83 Elmhurst, IL 60126
A36: Toyota | B36: 2015 | C36: Prius v Three | D36: Used | E36: 91655 | F36: 13980 | G36: 13980 | H36: No | J36: {'Exterior color': ' Attitude Black ', 'Interior color': 'Gray ', 'Drivetrain': 'Front-wheel Drive ', 'MPG': ' 44â€“40Based on EPA mileage ratings. Use for comparison purposes only. Actual mileage will vary depending on driving conditions, driving habits, vehicle maintenance, and other factors.', 'Fuel type': 'Gasoline ', 'Transmission': 'Automatic', 'Engine': '1.8L I-4 DOHC, VVT-i variable valve control, regular unleaded, e', 'VIN': ' JTDZN3EUXFJ016005 ', 'Stock #': ' 6069 ', 'Mileage': ' 91,655 mi. '} | K36: {'Accidents or damage': 'None reported', 'Clean title': 'Yes', '1-owner vehicle': 'No', 'Personal use only': 'Yes', 'Open recall': 'At least 1 open recall reported'} | L36: {'Comfort': '5.0', 'Interior': '5.0', 'Performance': '5.0', 'Value': '5.0', 'Exterior': '5.0', 'Reliability': '5.0'} | M36: 4.6 | N36: (189 reviews) | O36: 1886 S Elmhurst Rd Mt Prospect, IL 60056
A37: Mercedes-Benz | B37: 2024 | C37: AMG EQS Base | D37: New | E37: 6 | F37: $152,800 | G37: $152,800 | H37: No | I37: MSRP $152,800 | J37: {'Exterior color': ' Moonlight White ', 'Interior color': 'Black ', 'Drivetrain': 'All-wheel Drive ', 'Transmission': '1-Speed Automatic', 'Engine': 'Electric', 'VIN': ' W1KCG5FB6RA047125 ', 'Stock #': ' 64-592 ', 'Mileage': ' 6 mi. '} | K37: {} | L37: {} | M37: 4.7 | N37: (2,850 reviews) | O37: 1600 Frontage Rd Northbrook, IL 60062
A38: Toyota | B38: 2012 | C38: Prius v Two | D38: Used | E38: 168725 | F38: 9945 | G38: 9945 | H38: No | J38: {'Exterior color': ' Magnetic Gray Metallic ', 'Interior color': 'GRAY ', 'Drivetrain': 'Front-wheel Drive ', 'MPG': ' 0â€“0Based on EPA mileage ratings. Use for comparison purposes only. Actual mileage will vary depending on driving conditions, driving habits, vehicle maintenance, and other factors.', 'Fuel type': 'Hybrid ', 'Transmission': 'Automatic', 'Engine': '1.8L 4 CYLINDER', 'VIN': ' JTDZN3EU5C3136231 ', 'Stock #': ' 36231 ', 'Mileage': ' 168,725 mi. '} | K38: {'Accidents or damage': 'None reported', '1-owner vehicle': 'Yes', 'Personal use only': 'Yes'} | L38: {'Comfort': '5.0', 'Interior': '5.0', 'Performance': '5.0', 'Value': '5.0', 'Exterior': '5.0', 'Reliability': 'â€”'} | M38: 4.2 | N38: (20 reviews) | O38: 350 S Lalonde Ave ADDISON, IL 60101
A39: Chrysler | B39: 2008 | C39: Sebring Touring | D39: Used | E39: 70974 | F39: 11950 | G39: 11950 | H39: No | J39: {'Exterior color': ' Silver Steel Metallic Clearcoat ', 'Interior color': 'Dark Slate Gray/Light Slate Gray ', 'Drivetrain': 'Front-wheel Drive ', 'MPG': ' 18â€“26Based on EPA mileage ratings. Use for comparison purposes only. Actual mileage will vary depending on driving conditions, driving habits, vehicle maintenance, and other factors.', 'Fuel type': 'E85 Flex Fuel ', 'Transmission': 'Automatic', 'Engine': '2.7L V-6 DOHC, engine with 189HP', 'VIN': ' 1C3LC55R88N615598 ', 'Stock #': ' N615598 ', 'Mileage': ' 70,974 mi. '} | K39: {'Accidents or damage': 'None reported', '1-owner vehicle': 'No', 'Personal use only': 'Yes'} | L39: {} | M39: 4.6 | N39: (127 reviews) | O39: 1030 Republic Dr Addison, IL 60101
A40: Jeep | B40: 2007 | C40: Commander Sport | D40: Used | E40: 173694 | F40: $4,550$400 | G40: $4,550 | H40: Yes | J40: {'Exterior color': ' Light Graystone Pearlcoat ', 'Interior color': 'Khaki ', 'Drivetrain': 'Four-wheel Drive ', 'MPG': ' 16â€“19Based on EPA mileage ratings. Use for comparison purposes only. Actual mileage will vary depending on driving conditions, driving habits, vehicle maintenance, and other factors.', 'Fuel type': 'Gasoline ', 'Transmission': 'Automatic', 'Engine': 'Power Tech 3.7L V-6 regular unleaded, engine with 210HP', 'VIN': ' 1J8HG48K37C510145 ', 'Stock #': ' B-329 ', 'Mileage': ' 173,694 mi. '} | K40: {'Accidents or damage': 'At least 1 accident or damage reported', 'Clean title': 'Yes', '1-owner vehicle': 'No', 'Personal use only': 'Yes'} | L40: {} | O40: 11S344 Jeans Road Lemont, IL 60439
...

Sheet Clean Sheet
A1: Car_ID | B1: Make | C1: Year | D1: Condition | E1: Mileage | F1: Milage_Group | G1: Price_Drop | H1: Price | I1: Exterior_Color | J1: Interior _Color | K1: Drivetrain | L1: MPG | M1: Accident | N1: Seller_Rating
